Workbook

Sheet ⌨ Shortcuts
B1: KEYBOARD SHORTCUTS REFERENCE
B2: Financial Statement Model | All shortcuts for Excel on Windows (Mac: swap Ctrl ↔ Cmd)
B4: COLOR CONVENTION REMINDER
B5: Blue text | C5: Hardcoded inputs — safe to change
B6: Black text | C6: Formulas — do NOT overwrite
B7: Green text | C7: Cross-sheet links
B8: Yellow fill | C8: Key assumptions needing attention
B11: NAVIGATION | E11: FORMULAS & AUDITING
B12: Ctrl + Home | C12: Go to cell A1 | E12: F2 | F12: Enter edit mode in active cell
B13: Ctrl + End | C13: Go to last used cell | E13: F4 | F13: Toggle $absolute vs relative refs
B14: Ctrl + Arrow Keys | C14: Jump to edge of data region | E14: F9 | F14: Evaluate selected part of formula
B15: Ctrl + PgUp / PgDn | C15: Move between sheets | E15: Ctrl + ` | F15: Toggle show formulas vs values
B16: F5 (or Ctrl + G) | C16: Go To dialog | E16: Ctrl + [ | F16: Select direct precedents (blue arrows)
B17: Ctrl + F | C17: Find & Replace | E17: Ctrl + ] | F17: Select direct dependents
B18: Ctrl + Shift + F | C18: Find in all sheets (Acrobat style) | E18: Alt + M + P | F18: Trace Precedents (ribbon shortcut)
E19: Alt + M + D | F19: Trace Dependents
B20: SELECTION | E20: Alt + M + A + A | F20: Remove all tracer arrows
B21: Ctrl + Shift + End | C21: Select from cursor to last used cell | E21: Ctrl + Shift + F3 | F21: Create names from selection
B22: Ctrl + Shift + Arrow | C22: Extend selection to region edge
B23: Ctrl + Space | C23: Select entire column | E23: ROWS, COLUMNS & GROUPING
B24: Shift + Space | C24: Select entire row | E24: Ctrl + Shift + + | F24: Insert row or column
B25: Ctrl + A | C25: Select all (or current region) | E25: Ctrl + - | F25: Delete row or column
B26: Ctrl + Shift + * | C26: Select current region around cursor | E26: Alt + Shift + Right | F26: Group rows or columns
E27: Alt + Shift + Left | F27: Ungroup rows or columns
B28: FORMATTING | E28: Alt + A + H | F28: Hide / collapse group detail
B29: Ctrl + 1 | C29: Open Format Cells dialog (all formatting) | E29: Alt + A + J | F29: Show / expand group detail
B30: Ctrl + B | C30: Bold | E30: Ctrl + 9 | F30: Hide rows
B31: Ctrl + I | C31: Italic | E31: Ctrl + 0 | F31: Hide columns
B32: Ctrl + U | C32: Underline | E32: Ctrl + Shift + 9 | F32: Unhide rows
B33: Ctrl + Shift + $ | C33: Apply currency format | E33: Ctrl + Shift + 0 | F33: Unhide columns
B34: Ctrl + Shift + % | C34: Apply percentage format
B35: Ctrl + Shift + ! | C35: Apply number format (2 decimals) | E35: FILE & WORKBOOK
B36: Ctrl + Shift + ~ | C36: Apply general number format | E36: Ctrl + S | F36: Save
B37: Alt + H + H | C37: Fill color picker | E37: Ctrl + Z | F37: Undo
B38: Alt + H + F + C | C38: Font color picker | E38: Ctrl + Y | F38: Redo
E39: F12 | F39: Save As
B40: COPY, PASTE & FILL | E40: Ctrl + W | F40: Close workbook
B41: Ctrl + C | C41: Copy | E41: Ctrl + N | F41: New workbook
B42: Ctrl + V | C42: Paste | E42: Ctrl + O | F42: Open file
B43: Ctrl + X | C43: Cut | E43: Ctrl + P | F43: Print
...

Sheet Assumptions
B1: INTEGRATED FINANCIAL STATEMENT MODEL
B2: Wall Street Prep Framework — Data Scientist Edition
B3: Color Code: Blue = Hardcoded Input | Black = Formula | Green = Cross-Sheet Link
B5: ASSUMPTIONS & DRIVERS | C5: Label | D5: FY2020A | E5: FY2021A | F5: FY2022A | G5: FY2023E | H5: FY2024E | I5: FY2025E
B6: Revenue Assumptions
B7: Revenue Growth Rate (YoY %) | C7: rev_growth | D7: N/A | E7: 0.08 | F7: 0.12 | G7: 0.1 | H7: 0.09 | I7: 0.08
B8: Gross Margin (%) | C8: gp_margin | D8: 0.52 | E8: 0.54 | F8: 0.55 | G8: 0.56 | H8: 0.57 | I8: 0.57
D9: Anchor Revenue ($mm) | E9: 274515
B11: Operating Expense Assumptions
B12: R&D as % of Revenue | C12: rd_pct | D12: 0.071 | E12: 0.072 | F12: 0.073 | G12: 0.073 | H12: 0.074 | I12: 0.074
B13: SG&A as % of Revenue | C13: sga_pct | D13: 0.069 | E13: 0.068 | F13: 0.067 | G13: 0.067 | H13: 0.066 | I13: 0.066
B14: D&A as % of Revenue | C14: da_pct | D14: 0.04 | E14: 0.04 | F14: 0.039 | G14: 0.039 | H14: 0.038 | I14: 0.038
B15: SBC as % of Revenue | C15: sbc_pct | D15: 0.025 | E15: 0.026 | F15: 0.026 | G15: 0.026 | H15: 0.026 | I15: 0.026
B16: Effective Tax Rate (%) | C16: tax_rate | D16: 0.245 | E16: 0.252 | F16: 0.25 | G16: 0.25 | H16: 0.25 | I16: 0.25
B18: Working Capital Assumptions (Days)
B19: Days Sales Outstanding (DSO) | C19: dso | D19: 27 | E19: 27 | F19: 26 | G19: 26 | H19: 25 | I19: 25
B20: Days Inventory Outstanding (DIO) | C20: dio | D20: 8 | E20: 8 | F20: 7 | G20: 7 | H20: 7 | I20: 7
B21: Days Payable Outstanding (DPO) | C21: dpo | D21: 73 | E21: 73 | F21: 72 | G21: 72 | H21: 71 | I21: 71
B23: Capex & Financing Assumptions
B24: Capex as % of Revenue | C24: capex_pct | D24: 0.035 | E24: 0.035 | F24: 0.034 | G24: 0.034 | H24: 0.033 | I24: 0.033
B25: Interest Rate on Debt (%) | C25: int_rate | D25: 0.025 | E25: 0.025 | F25: 0.028 | G25: 0.03 | H25: 0.03 | I25: 0.03
B26: Dividend Payout Ratio (%) | C26: div_payout | D26: 0.21 | E26: 0.22 | F26: 0.22 | G26: 0.22 | H26: 0.23 | I26: 0.23
B27: Share Repurchase as % of NI | C27: buyback_pct | D27: 0.35 | E27: 0.35 | F27: 0.36 | G27: 0.36 | H27: 0.36 | I27: 0.36
B28: Minimum Cash Balance ($mm) | C28: min_cash | D28: 20000 | E28: 20000 | F28: 20000 | G28: 20000 | H28: 20000 | I28: 20000

Sheet Income Statement
B1: INCOME STATEMENT
B2: All figures in $mm unless otherwise noted
B4: INCOME STATEMENT ($mm) | C4: Driver | D4: FY2020A | E4: FY2021A | F4: FY2022A | G4: FY2023E | H4: FY2024E | I4: FY2025E
B5: Revenue
B6: Revenue | C6: rev_growth | D6: 274515 | E6: 365817 | F6: 394328 | G6: =F6*(1+Assumptions!G7) -> 433760.8 | H6: =G6*(1+Assumptions!H7) -> 472799.27 | I6: =H6*(1+Assumptions!I7) -> 510623.21
B7: YoY Growth (%) | D7: N/A | E7: =(E6-D6)/D6 -> 0.33259385 | F7: =(F6-E6)/E6 -> 0.077937876 | G7: =(G6-F6)/F6 -> 0.1 | H7: =(H6-G6)/G6 -> 0.09 | I7: =(I6-H6)/H6 -> 0.08
B9: Cost of Revenue & Gross Profit
B10: Cost of Revenue (COGS) | C10: gp_margin | D10: 169559 | E10: 212981 | F10: 223546 | G10: =G6*(1-Assumptions!G8) -> 190854.75 | H10: =H6*(1-Assumptions!H8) -> 203303.69 | I10: =I6*(1-Assumptions!I8) -> 219567.98
B11: Gross Profit | D11: =D6-D10 -> 104956 | E11: =E6-E10 -> 152836 | F11: =F6-F10 -> 170782 | G11: =G6-G10 -> 242906.05 | H11: =H6-H10 -> 269495.59 | I11: =I6-I10 -> 291055.23
B12: Gross Margin (%) | D12: =D11/D6 -> 0.38233248 | E12: =E11/E6 -> 0.4177936 | F12: =F11/F6 -> 0.43309631 | G12: =G11/G6 -> 0.56 | H12: =H11/H6 -> 0.57 | I12: =I11/I6 -> 0.57
B14: Operating Expenses
B15: R&D | C15: rd_pct | D15: 18752 | E15: 21914 | F15: 26251 | G15: =G6*Assumptions!G12 -> 31664.538 | H15: =H6*Assumptions!H12 -> 34987.146 | I15: =I6*Assumptions!I12 -> 37786.118
B16: SG&A | C16: sga_pct | D16: 19916 | E16: 21973 | F16: 25094 | G16: =G6*Assumptions!G13 -> 29061.974 | H16: =H6*Assumptions!H13 -> 31204.752 | I16: =I6*Assumptions!I13 -> 33701.132
B17: D&A | C17: da_pct | D17: 11056 | E17: 11284 | F17: 11104 | G17: =G6*Assumptions!G14 -> 16916.671 | H17: =H6*Assumptions!H14 -> 17966.372 | I17: =I6*Assumptions!I14 -> 19403.682
B18: Total Operating Expenses | D18: =SUM(D15:D17) -> 49724 | E18: =SUM(E15:E17) -> 55171 | F18: =SUM(F15:F17) -> 62449 | G18: =SUM(G15:G17) -> 77643.183 | H18: =SUM(H15:H17) -> 84158.27 | I18: =SUM(I15:I17) -> 90890.932
B20: EBIT / EBITDA
B21: EBIT (Operating Income) | D21: =D11-D18 -> 55232 | E21: =E11-E18 -> 97665 | F21: =F11-F18 -> 108333 | G21: =G11-G18 -> 165262.86 | H21: =H11-H18 -> 185337.31 | I21: =I11-I18 -> 200164.3
B22: EBIT Margin (%) | D22: =D21/D6 -> 0.20119848 | E22: =E21/E6 -> 0.26697775 | F22: =F21/F6 -> 0.27472815 | G22: =G21/G6 -> 0.381 | H22: =H21/H6 -> 0.392 | I22: =I21/I6 -> 0.392
B23: EBITDA (EBIT + D&A) | D23: =D21+D17 -> 66288 | E23: =E21+E17 -> 108949 | F23: =F21+F17 -> 119437 | G23: =G21+G17 -> 182179.54 | H23: =H21+H17 -> 203303.69 | I23: =I21+I17 -> 219567.98
B24: EBITDA Margin (%) | D24: =D23/D6 -> 0.24147314 | E24: =E23/E6 -> 0.29782378 | F24: =F23/F6 -> 0.30288744 | G24: =G23/G6 -> 0.42 | H24: =H23/H6 -> 0.43 | I24: =I23/I6 -> 0.43
B26: Below-the-Line & Net Income
B27: Interest Expense | C27: int_rate | D27: 3576 | E27: 2645 | F27: 2931 | G27: =F27*(G6/F6) -> 3224.1 | H27: =G27*(H6/G6) -> 3514.269 | I27: =H27*(I6/H6) -> 3795.4105
B28: Pretax Income (EBT) | D28: =D21-D27 -> 51656 | E28: =E21-E27 -> 95020 | F28: =F21-F27 -> 105402 | G28: =G21-G27 -> 162038.76 | H28: =H21-H27 -> 181823.05 | I28: =I21-I27 -> 196368.89
B29: Tax Expense | D29: =D28*Assumptions!D16 -> 12655.72 | E29: =E28*Assumptions!E16 -> 23945.04 | F29: =F28*Assumptions!F16 -> 26350.5 | G29: =G28*Assumptions!G16 -> 40509.691 | H29: =H28*Assumptions!H16 -> 45455.761 | I29: =I28*Assumptions!I16 -> 49092.222
B30: Net Income | D30: =D28-D29 -> 39000.28 | E30: =E28-E29 -> 71074.96 | F30: =F28-F29 -> 79051.5 | G30: =G28-G29 -> 121529.07 | H30: =H28-H29 -> 136367.28 | I30: =I28-I29 -> 147276.67
B31: Net Margin (%) | D31: =D30/D6 -> 0.14206976 | E31: =E30/E6 -> 0.19429103 | F31: =F30/F6 -> 0.20047143 | G31: =G30/G6 -> 0.28017533 | H31: =H30/H6 -> 0.28842533 | I31: =I30/I6 -> 0.28842533

Sheet Balance Sheet
B1: BALANCE SHEET
B2: All figures in $mm unless otherwise noted
B4: BALANCE SHEET ($mm) | C4: Driver | D4: FY2020A | E4: FY2021A | F4: FY2022A | G4: FY2023E | H4: FY2024E | I4: FY2025E
B5: CURRENT ASSETS
B6: Cash & Equivalents | C6: revolver | D6: 38016 | E6: 62639 | F6: 23646 | G6: =F6+'Cash Flow Statement'!G19 -> -8715.4484 | H6: =G6+'Cash Flow Statement'!H19 -> -46110.539 | I6: =H6+'Cash Flow Statement'!I19 -> -86303.277
B7: Accounts Receivable | C7: dso | D7: 16120 | E7: 26278 | F7: 28184 | G7: ='Income Statement'!G6/365*Assumptions!G19 -> 30898.03 | H7: ='Income Statement'!H6/365*Assumptions!H19 -> 32383.512 | I7: ='Income Statement'!I6/365*Assumptions!I19 -> 34974.193
B8: Inventory | C8: dio | D8: 4061 | E8: 6580 | F8: 4946 | G8: ='Income Statement'!G10/365*Assumptions!G20 -> 3660.2281 | H8: ='Income Statement'!H10/365*Assumptions!H20 -> 3898.9748 | I8: ='Income Statement'!I10/365*Assumptions!I20 -> 4210.8928
B9: Prepaid & Other Current | C9: rev_growth | D9: 14111 | E9: 21223 | F9: 16682 | G9: =F9*('Income Statement'!G6/'Income Statement'!F6) -> 18350.2 | H9: =G9*('Income Statement'!H6/'Income Statement'!G6) -> 20001.718 | I9: =H9*('Income Statement'!I6/'Income Statement'!H6) -> 21601.855
B10: Total Current Assets | C10: SUM | D10: =SUM(D6:D9) -> 72308 | E10: =SUM(E6:E9) -> 116720 | F10: =SUM(F6:F9) -> 73458 | G10: =SUM(G6:G9) -> 44193.009 | H10: =SUM(H6:H9) -> 10173.666 | I10: =SUM(I6:I9) -> -25516.336
B12: NON-CURRENT ASSETS
B13: PP&E, Net | C13: capex_pct | D13: 37378 | E13: 39440 | F13: 42117 | G13: =F13+'Cash Flow Statement'!G9-'Income Statement'!G17 -> 140684.98 | H13: =G13+'Cash Flow Statement'!H9-'Income Statement'!H17 -> 282111.47 | I13: =H13+'Cash Flow Statement'!I9-'Income Statement'!I17 -> 434382.07
B14: Other Non-Current Assets | D14: 32978 | E14: 53876 | F14: 54428 | G14: =F14*('Income Statement'!G6/'Income Statement'!F6) -> 59870.8 | H14: =G14*('Income Statement'!H6/'Income Statement'!G6) -> 65259.172 | I14: =H14*('Income Statement'!I6/'Income Statement'!H6) -> 70479.906
B15: Total Non-Current Assets | D15: =SUM(D13:D14) -> 70356 | E15: =SUM(E13:E14) -> 93316 | F15: =SUM(F13:F14) -> 96545 | G15: =SUM(G13:G14) -> 200555.78 | H15: =SUM(H13:H14) -> 347370.65 | I15: =SUM(I13:I14) -> 504861.98
B17: TOTAL ASSETS | D17: =D10+D15 -> 142664 | E17: =E10+E15 -> 210036 | F17: =F10+F15 -> 170003 | G17: =G10+G15 -> 244748.79 | H17: =H10+H15 -> 357544.31 | I17: =I10+I15 -> 479345.64
B19: CURRENT LIABILITIES
B20: Accounts Payable | C20: dpo | D20: 42296 | E20: 54763 | F20: 64115 | G20: ='Income Statement'!G10/365*Assumptions!G21 -> 37648.061 | H20: ='Income Statement'!H10/365*Assumptions!H21 -> 39546.745 | I20: ='Income Statement'!I10/365*Assumptions!I21 -> 42710.484
B21: Deferred Revenue | D21: 5522 | E21: 7612 | F21: 7912 | G21: =F21*('Income Statement'!G6/'Income Statement'!F6) -> 8703.2 | H21: =G21*('Income Statement'!H6/'Income Statement'!G6) -> 9486.488 | I21: =H21*('Income Statement'!I6/'Income Statement'!H6) -> 10245.407
B22: Other Accrued Liabilities | D22: 27920 | E22: 46236 | F22: 58111 | G22: =F22*('Income Statement'!G6/'Income Statement'!F6) -> 63922.1 | H22: =G22*('Income Statement'!H6/'Income Statement'!G6) -> 69675.089 | I22: =H22*('Income Statement'!I6/'Income Statement'!H6) -> 75249.096
B23: Total Current Liabilities | D23: =SUM(D20:D22) -> 75738 | E23: =SUM(E20:E22) -> 108611 | F23: =SUM(F20:F22) -> 130138 | G23: =SUM(G20:G22) -> 110273.36 | H23: =SUM(H20:H22) -> 118708.32 | I23: =SUM(I20:I22) -> 128204.99
B25: NON-CURRENT LIABILITIES
B26: Long-Term Debt | D26: 98667 | E26: 109106 | F26: 98959 | G26: =F26*0.98 -> 96979.82 | H26: =G26*0.98 -> 95040.224 | I26: =H26*0.98 -> 93139.419
B27: Other Non-Current Liabilities | D27: 54490 | E27: 53377 | F27: 49142 | G27: =F27*('Income Statement'!G6/'Income Statement'!F6) -> 54056.2 | H27: =G27*('Income Statement'!H6/'Income Statement'!G6) -> 58921.258 | I27: =H27*('Income Statement'!I6/'Income Statement'!H6) -> 63634.959
B28: Total Non-Current Liabilities | D28: =SUM(D26:D27) -> 153157 | E28: =SUM(E26:E27) -> 162483 | F28: =SUM(F26:F27) -> 148101 | G28: =SUM(G26:G27) -> 151036.02 | H28: =SUM(H26:H27) -> 153961.48 | I28: =SUM(I26:I27) -> 156774.38
B30: TOTAL LIABILITIES | D30: =D23+D28 -> 228895 | E30: =E23+E28 -> 271094 | F30: =F23+F28 -> 278239 | G30: =G23+G28 -> 261309.38 | H30: =H23+H28 -> 272669.8 | I30: =I23+I28 -> 284979.37
B32: SHAREHOLDERS' EQUITY
B33: Common Stock & APIC | D33: 65340 | E33: 57365 | F33: 64849 | G33: =F33 -> 64849 | H33: =G33 -> 64849 | I33: =H33 -> 64849
B34: Retained Earnings | D34: -3068 | E34: 5562 | F34: -3068 | G34: =F34+'Income Statement'!G30-'Cash Flow Statement'!G14-'Cash Flow Statement'!G15 -> 118461.07 | H34: =G34+'Income Statement'!H30-'Cash Flow Statement'!H14-'Cash Flow Statement'!H15 -> 254828.36 | I34: =H34+'Income Statement'!I30-'Cash Flow Statement'!I14-'Cash Flow Statement'!I15 -> 402105.02
B35: Other Comprehensive Income | D35: -406 | E35: -1776 | F35: -11109 | G35: =F35 -> -11109 | H35: =G35 -> -11109 | I35: =H35 -> -11109
B36: Total Shareholders' Equity | D36: =SUM(D33:D35) -> 61866 | E36: =SUM(E33:E35) -> 61151 | F36: =SUM(F33:F35) -> 50672 | G36: =SUM(G33:G35) -> 172201.07 | H36: =SUM(H33:H35) -> 308568.36 | I36: =SUM(I33:I35) -> 455845.02
B38: TOTAL LIABILITIES & EQUITY | D38: =D30+D36 -> 290761 | E38: =E30+E36 -> 332245 | F38: =F30+F36 -> 328911 | G38: =G30+G36 -> 433510.45 | H38: =H30+H36 -> 581238.16 | I38: =I30+I36 -> 740824.39
B40: Balance Check (Assets - L&E) → should be 0 | D40: =D17-D38 -> -148097 | E40: =E17-E38 -> -122209 | F40: =F17-F38 -> -158908 | G40: =G17-G38 -> -188761.67 | H40: =H17-H38 -> -223693.85 | I40: =I17-I38 -> -261478.75

Sheet Cash Flow Statement
B1: CASH FLOW STATEMENT
B2: All figures in $mm unless otherwise noted
B4: CASH FLOW STATEMENT ($mm) | C4: Driver | D4: FY2020A | E4: FY2021A | F4: FY2022A | G4: FY2023E | H4: FY2024E | I4: FY2025E
B5: CASH FROM OPERATIONS (CFO)
B6: Net Income | D6: ='Income Statement'!D30 -> 39000.28 | E6: ='Income Statement'!E30 -> 71074.96 | F6: ='Income Statement'!F30 -> 79051.5 | G6: ='Income Statement'!G30 -> 121529.07 | H6: ='Income Statement'!H30 -> 136367.28 | I6: ='Income Statement'!I30 -> 147276.67
B7: + Depreciation & Amortization | D7: ='Income Statement'!D17 -> 11056 | E7: ='Income Statement'!E17 -> 11284 | F7: ='Income Statement'!F17 -> 11104 | G7: ='Income Statement'!G17 -> 16916.671 | H7: ='Income Statement'!H17 -> 17966.372 | I7: ='Income Statement'!I17 -> 19403.682
B8: +/- Change in Working Capital | D8: -2452 | E8: -10809 | F8: 3826 | G8: =('Balance Sheet'!G23-'Balance Sheet'!F23)-('Balance Sheet'!G7-'Balance Sheet'!F7)-('Balance Sheet'!G8-'Balance Sheet'!F8)-('Balance Sheet'!G9-'Balance Sheet'!F9) -> -22961.097 | H8: =('Balance Sheet'!H23-'Balance Sheet'!G23)-('Balance Sheet'!H7-'Balance Sheet'!G7)-('Balance Sheet'!H8-'Balance Sheet'!G8)-('Balance Sheet'!H9-'Balance Sheet'!G9) -> 5059.214 | I8: =('Balance Sheet'!I23-'Balance Sheet'!H23)-('Balance Sheet'!I7-'Balance Sheet'!H7)-('Balance Sheet'!I8-'Balance Sheet'!H8)-('Balance Sheet'!I9-'Balance Sheet'!H9) -> 4993.9294
B9: Cash From Operations | D9: =SUM(D6:D8) -> 47604.28 | E9: =SUM(E6:E8) -> 71549.96 | F9: =SUM(F6:F8) -> 93981.5 | G9: =SUM(G6:G8) -> 115484.65 | H9: =SUM(H6:H8) -> 159392.87 | I9: =SUM(I6:I8) -> 171674.28
B11: CASH FROM INVESTING (CFI)
B12: Capital Expenditures | D12: -7309 | E12: -11085 | F12: -10708 | G12: =-('Income Statement'!G6*Assumptions!G24) -> -14747.867 | H12: =-('Income Statement'!H6*Assumptions!H24) -> -15602.376 | I12: =-('Income Statement'!I6*Assumptions!I24) -> -16850.566
B13: Cash From Investing | D13: =D12 -> -7309 | E13: =E12 -> -11085 | F13: =F12 -> -10708 | G13: =G12 -> -14747.867 | H13: =H12 -> -15602.376 | I13: =I12 -> -16850.566
B15: CASH FROM FINANCING (CFF)
B16: Debt Issuance / (Repayment) | D16: -7738 | E16: 12665 | F16: -9543 | G16: =-('Balance Sheet'!F26*0.02) -> -1979.18 | H16: =-('Balance Sheet'!G26*0.02) -> -1939.5964 | I16: =-('Balance Sheet'!H26*0.02) -> -1900.8045
B17: Dividends Paid | D17: -14081 | E17: -14467 | F17: -14841 | G17: =-('Income Statement'!G30*Assumptions!G25) -> -3645.8722 | H17: =-('Income Statement'!H30*Assumptions!H25) -> -4091.0185 | I17: =-('Income Statement'!I30*Assumptions!I25) -> -4418.3
B18: Share Repurchases | D18: -72516 | E18: -85971 | F18: -89402 | G18: =-('Income Statement'!G30*Assumptions!G26) -> -26736.396 | H18: =-('Income Statement'!H30*Assumptions!H26) -> -31364.475 | I18: =-('Income Statement'!I30*Assumptions!I26) -> -33873.633
B19: Cash From Financing | D19: =SUM(D16:D18) -> -94335 | E19: =SUM(E16:E18) -> -87773 | F19: =SUM(F16:F18) -> -113786 | G19: =SUM(G16:G18) -> -32361.448 | H19: =SUM(H16:H18) -> -37395.09 | I19: =SUM(I16:I18) -> -40192.738
B21: NET CHANGE IN CASH | D21: =D9+D13+D19 -> -54039.72 | E21: =E9+E13+E19 -> -27308.04 | F21: =F9+F13+F19 -> -30512.5 | G21: =G9+G13+G19 -> 68375.332 | H21: =H9+H13+H19 -> 106395.4 | I21: =I9+I13+I19 -> 114630.97
B23: FREE CASH FLOW (FCF) ANALYSIS
B24: EBITDA | D24: ='Income Statement'!D23 -> 66288 | E24: ='Income Statement'!E23 -> 108949 | F24: ='Income Statement'!F23 -> 119437 | G24: ='Income Statement'!G23 -> 182179.54 | H24: ='Income Statement'!H23 -> 203303.69 | I24: ='Income Statement'!I23 -> 219567.98
B25: Less: Capex | D25: =D12 -> -7309 | E25: =E12 -> -11085 | F25: =F12 -> -10708 | G25: =G12 -> -14747.867 | H25: =H12 -> -15602.376 | I25: =I12 -> -16850.566
B26: Less: Change in Working Capital | D26: =D8 -> -2452 | E26: =E8 -> -10809 | F26: =F8 -> 3826 | G26: =G8 -> -22961.097 | H26: =H8 -> 5059.214 | I26: =I8 -> 4993.9294
B27: Less: Cash Taxes | D27: =-'Income Statement'!D29 -> -12655.72 | E27: =-'Income Statement'!E29 -> -23945.04 | F27: =-'Income Statement'!F29 -> -26350.5 | G27: =-'Income Statement'!G29 -> -40509.691 | H27: =-'Income Statement'!H29 -> -45455.761 | I27: =-'Income Statement'!I29 -> -49092.222
B28: Unlevered Free Cash Flow | D28: =SUM(D24:D27) -> 43871.28 | E28: =SUM(E24:E27) -> 63109.96 | F28: =SUM(F24:F27) -> 86204.5 | G28: =SUM(G24:G27) -> 103960.88 | H28: =SUM(H24:H27) -> 147304.76 | I28: =SUM(I24:I27) -> 158619.12
B29: FCF Margin (%) | D29: =D28/'Income Statement'!D6 -> 0.15981378 | E29: =E28/'Income Statement'!E6 -> 0.17251784 | F29: =F28/'Income Statement'!F6 -> 0.21861116 | G29: =G28/'Income Statement'!G6 -> 0.2396733 | H29: =H28/'Income Statement'!H6 -> 0.31155878 | I29: =I28/'Income Statement'!I6 -> 0.31063829
B30: FCF Conversion (FCF / EBITDA) | D30: =IF(D24<>0,D28/D24,"-") -> 0.66182839 | E30: =IF(E24<>0,E28/E24,"-") -> 0.57926149 | F30: =IF(F24<>0,F28/F24,"-") -> 0.72175708 | G30: =IF(G24<>0,G28/G24,"-") -> 0.5706507 | H30: =IF(H24<>0,H28/H24,"-") -> 0.7245553 | I30: =IF(I24<>0,I28/I24,"-") -> 0.72241463

Sheet Summary Dashboard
B1: FINANCIAL MODEL SUMMARY DASHBOARD
B2: Key performance indicators and financial summary
B4: SUMMARY KPIs ($mm) | C4: Sheet | D4: FY2020A | E4: FY2021A | F4: FY2022A | G4: FY2023E | H4: FY2024E | I4: FY2025E
B5: INCOME STATEMENT HIGHLIGHTS
B6: Revenue ($mm) | C6: IS | D6: ='Income Statement'!D6 -> 274515 | E6: ='Income Statement'!E6 -> 365817 | F6: ='Income Statement'!F6 -> 394328 | G6: ='Income Statement'!G6 -> 433760.8 | H6: ='Income Statement'!H6 -> 472799.27 | I6: ='Income Statement'!I6 -> 510623.21
B7: YoY Growth | C7: IS | D7: N/A | E7: ='Income Statement'!E7 -> 0.33259385 | F7: ='Income Statement'!F7 -> 0.077937876 | G7: ='Income Statement'!G7 -> 0.1 | H7: ='Income Statement'!H7 -> 0.09 | I7: ='Income Statement'!I7 -> 0.08
B8: Gross Profit ($mm) | C8: IS | D8: ='Income Statement'!D11 -> 104956 | E8: ='Income Statement'!E11 -> 152836 | F8: ='Income Statement'!F11 -> 170782 | G8: ='Income Statement'!G11 -> 242906.05 | H8: ='Income Statement'!H11 -> 269495.59 | I8: ='Income Statement'!I11 -> 291055.23
B9: Gross Margin | C9: IS | D9: ='Income Statement'!D12 -> 0.38233248 | E9: ='Income Statement'!E12 -> 0.4177936 | F9: ='Income Statement'!F12 -> 0.43309631 | G9: ='Income Statement'!G12 -> 0.56 | H9: ='Income Statement'!H12 -> 0.57 | I9: ='Income Statement'!I12 -> 0.57
B10: EBIT ($mm) | C10: IS | D10: ='Income Statement'!D21 -> 55232 | E10: ='Income Statement'!E21 -> 97665 | F10: ='Income Statement'!F21 -> 108333 | G10: ='Income Statement'!G21 -> 165262.86 | H10: ='Income Statement'!H21 -> 185337.31 | I10: ='Income Statement'!I21 -> 200164.3
B11: EBIT Margin | C11: IS | D11: ='Income Statement'!D22 -> 0.20119848 | E11: ='Income Statement'!E22 -> 0.26697775 | F11: ='Income Statement'!F22 -> 0.27472815 | G11: ='Income Statement'!G22 -> 0.381 | H11: ='Income Statement'!H22 -> 0.392 | I11: ='Income Statement'!I22 -> 0.392
B12: EBITDA ($mm) | C12: IS | D12: ='Income Statement'!D23 -> 66288 | E12: ='Income Statement'!E23 -> 108949 | F12: ='Income Statement'!F23 -> 119437 | G12: ='Income Statement'!G23 -> 182179.54 | H12: ='Income Statement'!H23 -> 203303.69 | I12: ='Income Statement'!I23 -> 219567.98
B13: EBITDA Margin | C13: IS | D13: ='Income Statement'!D24 -> 0.24147314 | E13: ='Income Statement'!E24 -> 0.29782378 | F13: ='Income Statement'!F24 -> 0.30288744 | G13: ='Income Statement'!G24 -> 0.42 | H13: ='Income Statement'!H24 -> 0.43 | I13: ='Income Statement'!I24 -> 0.43
B14: Net Income ($mm) | C14: IS | D14: ='Income Statement'!D30 -> 39000.28 | E14: ='Income Statement'!E30 -> 71074.96 | F14: ='Income Statement'!F30 -> 79051.5 | G14: ='Income Statement'!G30 -> 121529.07 | H14: ='Income Statement'!H30 -> 136367.28 | I14: ='Income Statement'!I30 -> 147276.67
B15: Net Margin | C15: IS | D15: ='Income Statement'!D31 -> 0.14206976 | E15: ='Income Statement'!E31 -> 0.19429103 | F15: ='Income Statement'!F31 -> 0.20047143 | G15: ='Income Statement'!G31 -> 0.28017533 | H15: ='Income Statement'!H31 -> 0.28842533 | I15: ='Income Statement'!I31 -> 0.28842533
B17: CASH FLOW HIGHLIGHTS
B18: CFO ($mm) | C18: CFS | D18: ='Cash Flow Statement'!D9 -> 47604.28 | E18: ='Cash Flow Statement'!E9 -> 71549.96 | F18: ='Cash Flow Statement'!F9 -> 93981.5 | G18: ='Cash Flow Statement'!G9 -> 115484.65 | H18: ='Cash Flow Statement'!H9 -> 159392.87 | I18: ='Cash Flow Statement'!I9 -> 171674.28
B19: Capex ($mm) | C19: CFS | D19: ='Cash Flow Statement'!D12 -> -7309 | E19: ='Cash Flow Statement'!E12 -> -11085 | F19: ='Cash Flow Statement'!F12 -> -10708 | G19: ='Cash Flow Statement'!G12 -> -14747.867 | H19: ='Cash Flow Statement'!H12 -> -15602.376 | I19: ='Cash Flow Statement'!I12 -> -16850.566
B20: Free Cash Flow ($mm) | C20: CFS | D20: ='Cash Flow Statement'!D28 -> 43871.28 | E20: ='Cash Flow Statement'!E28 -> 63109.96 | F20: ='Cash Flow Statement'!F28 -> 86204.5 | G20: ='Cash Flow Statement'!G28 -> 103960.88 | H20: ='Cash Flow Statement'!H28 -> 147304.76 | I20: ='Cash Flow Statement'!I28 -> 158619.12
B21: FCF Margin | C21: CFS | D21: ='Cash Flow Statement'!D29 -> 0.15981378 | E21: ='Cash Flow Statement'!E29 -> 0.17251784 | F21: ='Cash Flow Statement'!F29 -> 0.21861116 | G21: ='Cash Flow Statement'!G29 -> 0.2396733 | H21: ='Cash Flow Statement'!H29 -> 0.31155878 | I21: ='Cash Flow Statement'!I29 -> 0.31063829
B23: BALANCE SHEET HIGHLIGHTS
B24: Cash & Equivalents ($mm) | C24: BS | D24: ='Balance Sheet'!D6 -> 38016 | E24: ='Balance Sheet'!E6 -> 62639 | F24: ='Balance Sheet'!F6 -> 23646 | G24: ='Balance Sheet'!G6 -> -8715.4484 | H24: ='Balance Sheet'!H6 -> -46110.539 | I24: ='Balance Sheet'!I6 -> -86303.277
B25: Total Assets ($mm) | C25: BS | D25: ='Balance Sheet'!D17 -> 142664 | E25: ='Balance Sheet'!E17 -> 210036 | F25: ='Balance Sheet'!F17 -> 170003 | G25: ='Balance Sheet'!G17 -> 244748.79 | H25: ='Balance Sheet'!H17 -> 357544.31 | I25: ='Balance Sheet'!I17 -> 479345.64
B26: Total Debt ($mm) | C26: BS | D26: ='Balance Sheet'!D26 -> 98667 | E26: ='Balance Sheet'!E26 -> 109106 | F26: ='Balance Sheet'!F26 -> 98959 | G26: ='Balance Sheet'!G26 -> 96979.82 | H26: ='Balance Sheet'!H26 -> 95040.224 | I26: ='Balance Sheet'!I26 -> 93139.419
B27: Net Debt ($mm) | C27: BS | D27: ='Balance Sheet'!D26-'Balance Sheet'!D6 -> 60651 | E27: ='Balance Sheet'!E26-'Balance Sheet'!E6 -> 46467 | F27: ='Balance Sheet'!F26-'Balance Sheet'!F6 -> 75313 | G27: ='Balance Sheet'!G26-'Balance Sheet'!G6 -> 105695.27 | H27: ='Balance Sheet'!H26-'Balance Sheet'!H6 -> 141150.76 | I27: ='Balance Sheet'!I26-'Balance Sheet'!I6 -> 179442.7
B28: Total Equity ($mm) | C28: BS | D28: ='Balance Sheet'!D36 -> 61866 | E28: ='Balance Sheet'!E36 -> 61151 | F28: ='Balance Sheet'!F36 -> 50672 | G28: ='Balance Sheet'!G36 -> 172201.07 | H28: ='Balance Sheet'!H36 -> 308568.36 | I28: ='Balance Sheet'!I36 -> 455845.02

Sheet Model Notes
B1: MODEL METHODOLOGY & DATA SCIENTIST NOTES
B3: OVERVIEW
B4: This model follows the Wall Street Prep integrated financial statement modeling framework.
B5: It is structured as a 3-statement model: Income Statement → Balance Sheet → Cash Flow Statement,
B6: all linked via a central Assumptions sheet. Color conventions follow industry standard.
B8: COLOR CODING
B9: BLUE = Hardcoded inputs (change these to run scenarios)
B10: BLACK = Formulas calculated within the sheet
B11: GREEN = Cross-sheet references (links to other tabs)
B13: FORECAST METHODOLOGY
B14: Revenue: Growth-rate driven from Assumptions sheet (rev_growth)
B15: Gross Profit: Margin-based (gp_margin × Revenue)
... B39: FCF: =EBITDA + Capex + ΔNWC – Cash_Taxes
